Workbook

Sheet Array Impedance
B2: WO-9001285
AO3: =Z20 -> 562 | AP3: =X21 -> 951 | AQ3: =Y22 -> 54 | AR3: =AA23 -> 61 | AS3: =AD24 -> 57 | AT3: =V24 -> 59 | AU3: =Z25 -> 58 | AV3: =AE26 -> 61 | AW3: A1 | BA3: =M55 -> 56 | BB3: =O54 -> 59 | BC3: =N53 -> 161 | BD3: =L52 -> 58 | BE3: =I51 -> 3041 | BF3: =Q51 -> 54 | BG3: =M50 -> <= 50 | BH3: =H49 -> <= 50 | BI3: A9
B4: SN: 11388-000003 | AO4: =Y20 -> 8290 | AP4: =W21 -> 61 | AQ4: =X22 -> 52 | AR4: =Z23 -> 52 | AS4: =AC24 -> 64 | AT4: =U24 -> 62 | AU4: =Y25 -> 65 | AV4: =AD26 -> 66 | AW4: array ID: 1078-3 | BA4: =N55 -> 61 | BB4: =P54 -> 59 | BC4: =O53 -> 57 | BD4: =M52 -> 52 | BE4: =J51 -> 64 | BF4: =R51 -> 63 | BG4: =N50 -> 53 | BH4: =I49 -> 54 | BI4: array ID: 1078-21
AO5: =X20 -> 55 | AP5: =V21 -> 58 | AQ5: =W22 -> 58 | AR5: =Y23 -> 63 | AS5: =AB24 -> 64 | AT5: =T24 -> 63 | AU5: =X25 -> 60 | AV5: =AC26 -> 66 | BA5: =O55 -> 60 | BB5: =Q54 -> 61 | BC5: =P53 -> 57 | BD5: =N52 -> 57 | BE5: =K51 -> 53 | BF5: =S51 -> 55 | BG5: =O50 -> <= 50 | BH5: =J49 -> 57
AO6: =W20 -> 59 | AP6: =U21 -> <= 50 | AQ6: =V22 -> 50 | AR6: =X23 -> <= 50 | AS6: =AA24 -> 66 | AT6: =AE25 -> 62 | AU6: =W25 -> 72 | AV6: =AB26 -> 61 | BA6: =P55 -> 62 | BB6: =R54 -> 58 | BC6: =Q53 -> 62 | BD6: =O52 -> 52 | BE6: =L51 -> 51 | BF6: =H50 -> 55 | BG6: =P50 -> 57 | BH6: =K49 -> 57
AO7: =V20 -> 50 | AP7: =T21 -> <= 50 | AQ7: =U22 -> 59 | AR7: =W23 -> 60 | AS7: =Z24 -> 65 | AT7: =AD25 -> 65 | AU7: =V25 -> 67 | AV7: =AA26 -> 66 | BA7: =Q55 -> 64 | BB7: =S54 -> 63 | BC7: =R53 -> 61 | BD7: =P52 -> 58 | BE7: =M51 -> <= 50 | BF7: =I50 -> 60 | BG7: =Q50 -> 57 | BH7: =L49 -> 57
AO8: =AA21 -> <= 50 | AP8: =AB22 -> <= 50 | AQ8: =T22 -> <= 50 | AR8: =V23 -> 51 | AS8: =Y24 -> 62 | AT8: =AC25 -> 68 | AU8: =U25 -> 68 | AV8: =Z26 -> 67 | BA8: =L54 -> 59 | BB8: =K53 -> 61 | BC8: =S53 -> 60 | BD8: =Q52 -> 62 | BE8: =N51 -> 53 | BF8: =J50 -> 56 | BG8: =R50 -> 57 | BH8: =M49 -> 57
AO9: =Z21 -> <= 50 | AP9: =AA22 -> <= 50 | AQ9: =AC23 -> 58 | AR9: =U23 -> 54 | AS9: =X24 -> 65 | AT9: =AB25 -> 63 | AU9: =T25 -> 63 | AV9: =Y26 -> 60 | BA9: =M54 -> 61 | BB9: =L53 -> 58 | BC9: =J52 -> 60 | BD9: =R52 -> 64 | BE9: =O51 -> 52 | BF9: =K50 -> 53 | BG9: =S50 -> 57 | BH9: =N49 -> 52
AO10: =Y21 -> 50 | AP10: =Z22 -> 52 | AQ10: =AB23 -> 54 | AR10: =T23 -> <= 50 | AS10: =W24 -> 65 | AT10: =AA25 -> 66 | AU10: =AF26 -> 67 | AV10: =X26 -> 61 | BA10: =N54 -> 57 | BB10: =M53 -> 54 | BC10: =K52 -> 66 | BD10: =S52 -> 72 | BE10: =P51 -> 51 | BF10: =L50 -> 55 | BG10: =G49 -> <= 50 | BH10: =O49 -> 53
AO12: =W26 -> 4652 | AP12: =AC27 -> <= 50 | AQ12: =U27 -> 59 | AR12: =AB28 -> 65 | AS12: =T28 -> 54 | AT12: =AB29 -> 57 | AU12: =T29 -> 56 | AV12: =AC30 -> 58 | AW12: A2 | BA12: =P49 -> 57 | BB12: =J48 -> 59 | BC12: =R48 -> 57 | BD12: =K47 -> 62 | BE12: =S47 -> 59 | BF12: =K46 -> 55 | BG12: =S46 -> 60 | BH12: =J45 -> 60 | BI12: A10
AO13: =V26 -> 55 | AP13: =AB27 -> 55 | AQ13: =T27 -> 66 | AR13: =AA28 -> 61 | AS13: =AI29 -> 56 | AT13: =AA29 -> <= 50 | AU13: =AJ30 -> 52 | AV13: =AB30 -> 52 | AW13: array ID: 1078-5 | BA13: =Q49 -> 60 | BB13: =K48 -> 52 | BC13: =S48 -> 55 | BD13: =L47 -> 56 | BE13: =D46 -> 64 | BF13: =L46 -> 64 | BG13: =C45 -> 64 | BH13: =K45 -> 54 | BI13: array ID: 1078-23
AO14: =U26 -> 59 | AP14: =AA27 -> 66 | AQ14: =AH28 -> 65 | AR14: =Z28 -> 70 | AS14: =AH29 -> 56 | AT14: =Z29 -> 58 | AU14: =AI30 -> 55 | AV14: =AA30 -> 57 | BA14: =R49 -> 60 | BB14: =L48 -> 59 | BC14: =E47 -> 58 | BD14: =M47 -> 63 | BE14: =E46 -> 64 | BF14: =M46 -> 64 | BG14: =D45 -> 62 | BH14: =L45 -> 69
AO15: =T26 -> 53 | AP15: =Z27 -> 61 | AQ15: =AG28 -> 65 | AR15: =Y28 -> 66 | AS15: =AG29 -> 58 | AT15: =Y29 -> <= 50 | AU15: =AH30 -> <= 50 | AV15: =Z30 -> <= 50 | BA15: =S49 -> 66 | BB15: =M48 -> 51 | BC15: =F47 -> 52 | BD15: =N47 -> 52 | BE15: =F46 -> 65 | BF15: =N46 -> 62 | BG15: =E45 -> 69 | BH15: =M45 -> 76
AO16: =AG27 -> 54 | AP16: =Y27 -> 70 | AQ16: =AF28 -> 69 | AR16: =X28 -> 68 | AS16: =AF29 -> 50 | AT16: =X29 -> <= 50 | AU16: =AG30 -> 54 | AV16: =Y30 -> 54 | BA16: =F48 -> 114 | BB16: =N48 -> 54 | BC16: =G47 -> 58 | BD16: =O47 -> 59 | BE16: =G46 -> 66 | BF16: =O46 -> 67 | BG16: =F45 -> 66 | BH16: =N45 -> 57
AO17: =AF27 -> 53 | AP17: =X27 -> 64 | AQ17: =AE28 -> 65 | AR17: =W28 -> 65 | AS17: =AE29 -> <= 50 | AT17: =W29 -> 51 | AU17: =AF30 -> <= 50 | AV17: =X30 -> <= 50 | BA17: =G48 -> <= 50 | BB17: =O48 -> 60 | BC17: =H47 -> <= 50 | BD17: =P47 -> 53 | BE17: =H46 -> 63 | BF17: =P46 -> 67 | BG17: =G45 -> 66 | BH17: =O45 -> 65
M18: Electrode impedance viewing from bottom (wire bonding side) | AO18: =AE27 -> 59 | AP18: =W27 -> 69 | AQ18: =AD28 -> 69 | AR18: =V28 -> 66 | AS18: =AD29 -> <= 50 | AT18: =V29 -> <= 50 | AU18: =AE30 -> 55 | AV18: =W30 -> 50 | BA18: =H48 -> <= 50 | BB18: =P48 -> 50 | BC18: =I47 -> 55 | BD18: =Q47 -> 56 | BE18: =I46 -> 60 | BF18: =Q46 -> 65 | BG18: =H45 -> 64 | BH18: =P45 -> 65
AO19: =AD27 -> <= 50 | AP19: =V27 -> 60 | AQ19: =AC28 -> 68 | AR19: =U28 -> 65 | AS19: =AC29 -> 51 | AT19: =U29 -> 52 | AU19: =AD30 -> 51 | AV19: =V30 -> <= 50 | BA19: =I48 -> 65 | BB19: =Q48 -> 58 | BC19: =J47 -> 62 | BD19: =R47 -> 55 | BE19: =J46 -> 65 | BF19: =R46 -> 64 | BG19: =I45 -> 65 | BH19: =Q45 -> 191
M20: ='AutoZ data'!BA61 -> 60 | N20: ='AutoZ data'!BA62 -> 63 | O20: ='AutoZ data'!BA63 -> 66 | P20: ='AutoZ data'!BA64 -> 62 | Q20: ='AutoZ data'!BA65 -> 58 | R20: R 7 | S20: R 8 | T20: R 2 | U20: R 1 | V20: ='AutoZ data'!C6 -> 50 | W20: ='AutoZ data'!C5 -> 59 | X20: ='AutoZ data'!C4 -> 55 | Y20: ='AutoZ data'!C3 -> 8290 | Z20: ='AutoZ data'!C2 -> 562
L21: ='AutoZ data'!BA53 -> 70 | M21: ='AutoZ data'!BA54 -> 65 | N21: ='AutoZ data'!BA55 -> 65 | O21: ='AutoZ data'!BA56 -> 63 | P21: ='AutoZ data'!BA57 -> 66 | Q21: ='AutoZ data'!BA58 -> 59 | R21: ='AutoZ data'!BA59 -> 64 | S21: ='AutoZ data'!BA60 -> 65 | T21: ='AutoZ data'!C14 -> <= 50 | U21: ='AutoZ data'!C$13 -> <= 50 | V21: ='AutoZ data'!C12 -> 58 | W21: ='AutoZ data'!C11 -> 61 | X21: ='AutoZ data'!C10 -> 951 | Y21: ='AutoZ data'!C9 -> 50 | Z21: ='AutoZ data'!C8 -> <= 50 | AA21: ='AutoZ data'!C7 -> <= 50 | AO21: =U30 -> 54 | AP21: =AE31 -> 60 | AQ21: =W31 -> 57 | AR21: =AG32 -> 57 | AS21: =Y32 -> 2206 | AT21: =AI33 -> 57 | AU21: =AA33 -> 55 | AV21: =AK34 -> 57 | AW21: A3 | BA21: =R45 -> 3028 | BB21: =H44 -> 63 | BC21: =P44 -> 62 | BD21: =F43 -> 64 | BE21: =N43 -> 60 | BF21: =D42 -> 62 | BG21: =L42 -> 60 | BH21: =B41 -> 61 | BI21: A11
K22: ='AutoZ data'!BA44 -> 64 | L22: ='AutoZ data'!BA45 -> 62 | M22: ='AutoZ data'!BA46 -> 66 | N22: ='AutoZ data'!BA47 -> 66 | O22: ='AutoZ data'!BA48 -> 63 | P22: ='AutoZ data'!BA49 -> 63 | Q22: ='AutoZ data'!BA50 -> 64 | R22: ='AutoZ data'!BA51 -> 64 | S22: ='AutoZ data'!BA52 -> 62 | T22: ='AutoZ data'!C23 -> <= 50 | U22: ='AutoZ data'!C22 -> 59 | V22: ='AutoZ data'!C21 -> 50 | W22: ='AutoZ data'!C20 -> 58 | X22: ='AutoZ data'!C19 -> 52 | Y22: ='AutoZ data'!C18 -> 54 | Z22: ='AutoZ data'!C17 -> 52 | AA22: ='AutoZ data'!C16 -> <= 50 | AB22: ='AutoZ data'!C15 -> <= 50 | AO22: =T30 -> 62 | AP22: =AD31 -> 62 | AQ22: =V31 -> 61 | AR22: =AF32 -> 59 | AS22: =X32 -> 56 | AT22: =AH33 -> <= 50 | AU22: =Z33 -> 58 | AV22: =AJ34 -> 53 | AW22: array ID: 1078-7 | BA22: =S45 -> 62 | BB22: =I44 -> 56 | BC22: =Q44 -> 64 | BD22: =G43 -> 60 | BE22: =O43 -> 62 | BF22: =E42 -> 53 | BG22: =M42 -> 58 | BH22: =C41 -> 55 | BI22: array ID: 1078-25
J23: ='AutoZ data'!BA34 -> 60 | K23: ='AutoZ data'!BA35 -> 65 | L23: ='AutoZ data'!BA36 -> 64 | M23: ='AutoZ data'!BA37 -> 65 | N23: ='AutoZ data'!BA38 -> 66 | O23: ='AutoZ data'!BA39 -> 63 | P23: ='AutoZ data'!BA40 -> 65 | Q23: ='AutoZ data'!BA41 -> 64 | R23: ='AutoZ data'!BA42 -> 63 | S23: ='AutoZ data'!BA43 -> 64 | T23: ='AutoZ data'!C33 -> <= 50 | U23: ='AutoZ data'!C32 -> 54 | V23: ='AutoZ data'!C31 -> 51 | W23: ='AutoZ data'!C30 -> 60 | X23: ='AutoZ data'!C29 -> <= 50 | Y23: ='AutoZ data'!C28 -> 63 | Z23: ='AutoZ data'!C27 -> 52 | AA23: ='AutoZ data'!C26 -> 61 | AB23: ='AutoZ data'!C25 -> 54 | AC23: ='AutoZ data'!C24 -> 58 | AO23: =AK31 -> 58 | AP23: =AC31 -> 60 | AQ23: =U31 -> 57 | AR23: =AE32 -> 61 | AS23: =W32 -> 59 | AT23: =AG33 -> 59 | AU23: =Y33 -> 55 | AV23: =AI34 -> 58 | BA23: =B44 -> 65 | BB23: =J44 -> 65 | BC23: =R44 -> 62 | BD23: =H43 -> 65 | BE23: =P43 -> 63 | BF23: =F42 -> 64 | BG23: =N42 -> 61 | BH23: =D41 -> 63
I24: ='AutoZ data'!BA23 -> <= 50 | J24: ='AutoZ data'!BA24 -> 63 | K24: ='AutoZ data'!BA25 -> 57 | L24: ='AutoZ data'!BA26 -> 61 | M24: ='AutoZ data'!BA27 -> 55 | N24: ='AutoZ data'!BA28 -> 62 | O24: ='AutoZ data'!BA29 -> 51 | P24: ='AutoZ data'!BA30 -> 59 | Q24: ='AutoZ data'!BA31 -> 53 | R24: ='AutoZ data'!BA32 -> 56 | S24: ='AutoZ data'!BA33 -> 53 | T24: ='AutoZ data'!C44 -> 63 | U24: ='AutoZ data'!C43 -> 62 | V24: ='AutoZ data'!C42 -> 59 | W24: ='AutoZ data'!C41 -> 65 | X24: ='AutoZ data'!C40 -> 65 | Y24: ='AutoZ data'!C39 -> 62 | Z24: ='AutoZ data'!C38 -> 65 | AA24: ='AutoZ data'!C37 -> 66 | AB24: ='AutoZ data'!C36 -> 64 | AC24: ='AutoZ data'!C35 -> 64 | AD24: ='AutoZ data'!C34 -> 57 | AO24: =AJ31 -> 61 | AP24: =AB31 -> 59 | AQ24: =T31 -> 64 | AR24: =AD32 -> 56 | AS24: =V32 -> 52 | AT24: =AF33 -> 52 | AU24: =X33 -> 56 | AV24: =AH34 -> 57 | BA24: =C44 -> 58 | BB24: =K44 -> 60 | BC24: =S44 -> 63 | BD24: =I43 -> 63 | BE24: =Q43 -> 64 | BF24: =G42 -> 52 | BG24: =O42 -> 53 | BH24: =E41 -> 52
H25: ='AutoZ data'!BA11 -> 51 | I25: ='AutoZ data'!BA12 -> 62 | J25: ='AutoZ data'!BA13 -> 51 | K25: ='AutoZ data'!BA14 -> 55 | L25: ='AutoZ data'!BA15 -> 61 | M25: ='AutoZ data'!BA16 -> 58 | N25: ='AutoZ data'!BA17 -> 58 | O25: ='AutoZ data'!BA18 -> 59 | P25: ='AutoZ data'!BA19 -> 56 | Q25: ='AutoZ data'!BA20 -> 60 | R25: ='AutoZ data'!BA21 -> 54 | S25: ='AutoZ data'!BA22 -> 63 | T25: ='AutoZ data'!C56 -> 63 | U25: ='AutoZ data'!C55 -> 68 | V25: ='AutoZ data'!C54 -> 67 | W25: ='AutoZ data'!C53 -> 72 | X25: ='AutoZ data'!C52 -> 60 | Y25: ='AutoZ data'!C51 -> 65 | Z25: ='AutoZ data'!C50 -> 58 | AA25: ='AutoZ data'!C49 -> 66 | AB25: ='AutoZ data'!C48 -> 63 | AC25: ='AutoZ data'!C47 -> 68 | AD25: ='AutoZ data'!C46 -> 65 | AE25: ='AutoZ data'!C45 -> 62 | AO25: =AI31 -> 63 | AP25: =AA31 -> 6253 | AQ25: =AK32 -> 60 | AR25: =AC32 -> 60 | AS25: =U32 -> 57 | AT25: =AE33 -> 59 | AU25: =W33 -> 57 | AV25: =AG34 -> 55 | BA25: =D44 -> 64 | BB25: =L44 -> 66 | BC25: =B43 -> 65 | BD25: =J43 -> 61 | BE25: =R43 -> 61 | BF25: =H42 -> 55 | BG25: =P42 -> 61 | BH25: =F41 -> 57
G26: ='AutoZ data'!AV94 -> 50 | H26: ='AutoZ data'!AV95 -> 54 | I26: ='AutoZ data'!AV96 -> 50 | J26: ='AutoZ data'!AV97 -> 51 | K26: ='AutoZ data'!BA2 -> <= 50 | L26: ='AutoZ data'!BA3 -> 59 | M26: ='AutoZ data'!BA4 -> 60 | N26: ='AutoZ data'!BA5 -> 61 | O26: ='AutoZ data'!BA6 -> 75 | P26: ='AutoZ data'!BA7 -> <= 50 | Q26: ='AutoZ data'!BA8 -> 390 | R26: ='AutoZ data'!BA9 -> 57 | S26: ='AutoZ data'!BA10 -> 59 | T26: ='AutoZ data'!C69 -> 53 | U26: ='AutoZ data'!C68 -> 59 | V26: ='AutoZ data'!C67 -> 55 | W26: ='AutoZ data'!C66 -> 4652 | X26: ='AutoZ data'!C65 -> 61 | Y26: ='AutoZ data'!C64 -> 60 | Z26: ='AutoZ data'!C63 -> 67 | AA26: ='AutoZ data'!C62 -> 66 | AB26: ='AutoZ data'!C61 -> 61 | AC26: ='AutoZ data'!C60 -> 66 | AD26: ='AutoZ data'!C59 -> 66 | AE26: ='AutoZ data'!C58 -> 61 | AF26: ='AutoZ data'!C57 -> 67 | AO26: =AH31 -> 59 | AP26: =Z31 -> 60 | AQ26: =AJ32 -> 60 | AR26: =AB32 -> 64 | AS26: =T32 -> 51 | AT26: =AD33 -> 53 | AU26: =V33 -> 54 | AV26: =AF34 -> 54 | BA26: =E44 -> 55 | BB26: =M44 -> 60 | BC26: =C43 -> 61 | BD26: =K43 -> 62 | BE26: =S43 -> <= 50 | BF26: =I42 -> 59 | BG26: =Q42 -> <= 50 | BH26: =G41 -> 51
F27: ='AutoZ data'!AV80 -> 52 | G27: ='AutoZ data'!AV81 -> 52 | H27: ='AutoZ data'!AV82 -> <= 50 | I27: ='AutoZ data'!AV83 -> <= 50 | J27: ='AutoZ data'!AV84 -> <= 50 | K27: ='AutoZ data'!AV85 -> 51 | L27: ='AutoZ data'!AV86 -> 51 | M27: ='AutoZ data'!AV87 -> 50 | N27: ='AutoZ data'!AV88 -> 50 | O27: ='AutoZ data'!AV89 -> 51 | P27: ='AutoZ data'!AV90 -> <= 50 | Q27: ='AutoZ data'!AV91 -> 54 | R27: ='AutoZ data'!AV92 -> <= 50 | S27: ='AutoZ data'!AV93 -> 50 | T27: ='AutoZ data'!C83 -> 66 | U27: ='AutoZ data'!C82 -> 59 | V27: ='AutoZ data'!C81 -> 60 | W27: ='AutoZ data'!C80 -> 69 | X27: ='AutoZ data'!C79 -> 64 | Y27: ='AutoZ data'!C78 -> 70 | Z27: ='AutoZ data'!C77 -> 61 | AA27: ='AutoZ data'!C76 -> 66 | AB27: ='AutoZ data'!C75 -> 55 | AC27: ='AutoZ data'!C74 -> <= 50 | AD27: ='AutoZ data'!C73 -> <= 50 | AE27: ='AutoZ data'!C72 -> 59 | AF27: ='AutoZ data'!C71 -> 53 | AG27: ='AutoZ data'!C70 -> 54 | AO27: =AG31 -> 59 | AP27: =Y31 -> 57 | AQ27: =AI32 -> 59 | AR27: =AA32 -> 60 | AS27: =AK33 -> 58 | AT27: =AC33 -> <= 50 | AU27: =U33 -> <= 50 | AV27: =AE34 -> 53 | BA27: =F44 -> 60 | BB27: =N44 -> 63 | BC27: =D43 -> 62 | BD27: =L43 -> 7564 | BE27: =B42 -> 54 | BF27: =J42 -> 55 | BG27: =R42 -> 61 | BH27: =H41 -> 52
E28: ='AutoZ data'!AV65 -> 58 | F28: ='AutoZ data'!AV66 -> 1833 | G28: ='AutoZ data'!AV67 -> 54 | H28: ='AutoZ data'!AV68 -> 51 | I28: ='AutoZ data'!AV69 -> <= 50 | J28: ='AutoZ data'!AV70 -> 50 | K28: ='AutoZ data'!AV71 -> <= 50 | L28: ='AutoZ data'!AV72 -> 51 | M28: ='AutoZ data'!AV73 -> <= 50 | N28: ='AutoZ data'!AV74 -> <= 50 | O28: ='AutoZ data'!AV75 -> 53 | P28: ='AutoZ data'!AV76 -> 50 | Q28: ='AutoZ data'!AV77 -> 50 | R28: ='AutoZ data'!AV78 -> 52 | S28: ='AutoZ data'!AV79 -> <= 50 | T28: ='AutoZ data'!H2 -> 54 | U28: ='AutoZ data'!C97 -> 65 | V28: ='AutoZ data'!C96 -> 66 | W28: ='AutoZ data'!C95 -> 65 | X28: ='AutoZ data'!C94 -> 68 | Y28: ='AutoZ data'!C93 -> 66 | Z28: ='AutoZ data'!C92 -> 70 | AA28: ='AutoZ data'!C91 -> 61 | AB28: ='AutoZ data'!C90 -> 65 | AC28: ='AutoZ data'!C89 -> 68 | AD28: ='AutoZ data'!C88 -> 69 | AE28: ='AutoZ data'!C87 -> 65 | AF28: ='AutoZ data'!C86 -> 69 | AG28: ='AutoZ data'!C85 -> 65 | AH28: ='AutoZ data'!C84 -> 65 | AO28: =AF31 -> 59 | AP28: =X31 -> 58 | AQ28: =AH32 -> 61 | AR28: =Z32 -> 56 | AS28: =AJ33 -> 52 | AT28: =AB33 -> 54 | AU28: =T33 -> 4953 | AV28: =AD34 -> 51 | BA28: =G44 -> 70 | BB28: =O44 -> 55 | BC28: =E43 -> 61 | BD28: =M43 -> 56 | BE28: =C42 -> 55 | BF28: =K42 -> 57 | BG28: =S42 -> 55 | BH28: =I41 -> 54
D29: ='AutoZ data'!AV49 -> 54 | E29: ='AutoZ data'!AV50 -> 53 | F29: ='AutoZ data'!AV51 -> 72 | G29: ='AutoZ data'!AV52 -> 50 | H29: ='AutoZ data'!AV53 -> 54 | I29: ='AutoZ data'!AV54 -> 54 | J29: ='AutoZ data'!AV55 -> 53 | K29: ='AutoZ data'!AV56 -> 54 | L29: ='AutoZ data'!AV57 -> 57 | M29: ='AutoZ data'!AV58 -> 61 | N29: ='AutoZ data'!AV59 -> 57 | O29: ='AutoZ data'!AV60 -> 56 | P29: ='AutoZ data'!AV61 -> 51 | Q29: ='AutoZ data'!AV62 -> 53 | R29: ='AutoZ data'!AV63 -> 56 | S29: ='AutoZ data'!AV64 -> 61 | T29: ='AutoZ data'!H18 -> 56 | U29: ='AutoZ data'!H17 -> 52 | V29: ='AutoZ data'!H16 -> <= 50 | W29: ='AutoZ data'!H15 -> 51 | X29: ='AutoZ data'!H14 -> <= 50 | Y29: ='AutoZ data'!H13 -> <= 50 | Z29: ='AutoZ data'!H12 -> 58 | AA29: ='AutoZ data'!H11 -> <= 50 | AB29: ='AutoZ data'!H10 -> 57 | AC29: ='AutoZ data'!H9 -> 51 | AD29: ='AutoZ data'!H8 -> <= 50 | AE29: ='AutoZ data'!H7 -> <= 50 | AF29: ='AutoZ data'!H6 -> 50 | AG29: ='AutoZ data'!H5 -> 58 | AH29: ='AutoZ data'!H4 -> 56 | AI29: ='AutoZ data'!H3 -> 56
C30: ='AutoZ data'!AV32 -> <= 50 | D30: ='AutoZ data'!AV33 -> 56 | E30: ='AutoZ data'!AV34 -> 52 | F30: ='AutoZ data'!AV35 -> 55 | G30: ='AutoZ data'!AV36 -> 54 | H30: ='AutoZ data'!AV37 -> 53 | I30: ='AutoZ data'!AV38 -> 55 | J30: ='AutoZ data'!AV39 -> 52 | K30: ='AutoZ data'!AV40 -> 56 | L30: ='AutoZ data'!AV41 -> 54 | M30: ='AutoZ data'!AV42 -> 55 | N30: ='AutoZ data'!AV43 -> 52 | O30: ='AutoZ data'!AV44 -> 56 | P30: ='AutoZ data'!AV45 -> <= 50 | Q30: ='AutoZ data'!AV46 -> 58 | R30: ='AutoZ data'!AV47 -> 53 | S30: ='AutoZ data'!AV48 -> 55 | T30: ='AutoZ data'!H35 -> 62 | U30: ='AutoZ data'!H34 -> 54 | V30: ='AutoZ data'!H33 -> <= 50 | W30: ='AutoZ data'!H32 -> 50 | X30: ='AutoZ data'!H31 -> <= 50 | Y30: ='AutoZ data'!H30 -> 54 | Z30: ='AutoZ data'!H29 -> <= 50 | AA30: ='AutoZ data'!H28 -> 57 | AB30: ='AutoZ data'!H27 -> 52 | AC30: ='AutoZ data'!H26 -> 58 | AD30: ='AutoZ data'!H25 -> 51 | AE30: ='AutoZ data'!H24 -> 55 | AF30: ='AutoZ data'!H23 -> <= 50 | AG30: ='AutoZ data'!H22 -> 54 | AH30: ='AutoZ data'!H21 -> <= 50 | AI30: ='AutoZ data'!H20 -> 55 | AJ30: ='AutoZ data'!H19 -> 52 | AO30: =AC34 -> 59 | AP30: =U34 -> 58 | AQ30: =AE35 -> 56 | AR30: =W35 -> 54 | AS30: =AG36 -> 57 | AT30: =Y36 -> 58 | AU30: =AI37 -> 60 | AV30: =AA37 -> 59 | AW30: A4 | BA30: =J41 -> 60 | BB30: =R41 -> 63 | BC30: =H40 -> 64 | BD30: =P40 -> 63 | BE30: =F39 -> 1459 | BF30: =N39 -> 61 | BG30: =D38 -> 60 | BH30: =L38 -> 61 | BI30: A12
B31: ='AutoZ data'!AV14 -> <= 50 | C31: ='AutoZ data'!AV15 -> 56 | D31: ='AutoZ data'!AV16 -> <= 50 | E31: ='AutoZ data'!AV17 -> 54 | F31: ='AutoZ data'!AV18 -> <= 50 | G31: ='AutoZ data'!AV19 -> <= 50 | H31: ='AutoZ data'!AV20 -> <= 50 | I31: ='AutoZ data'!AV21 -> <= 50 | J31: ='AutoZ data'!AV22 -> 51 | K31: ='AutoZ data'!AV23 -> <= 50 | L31: ='AutoZ data'!AV24 -> <= 50 | M31: ='AutoZ data'!AV25 -> 51 | N31: ='AutoZ data'!AV26 -> <= 50 | O31: ='AutoZ data'!AV27 -> <= 50 | P31: ='AutoZ data'!AV28 -> 52 | Q31: ='AutoZ data'!AV29 -> <= 50 | R31: ='AutoZ data'!AV30 -> <= 50 | S31: ='AutoZ data'!AV31 -> <= 50 | T31: ='AutoZ data'!H53 -> 64 | U31: ='AutoZ data'!H52 -> 57 | V31: ='AutoZ data'!H51 -> 61 | W31: ='AutoZ data'!H50 -> 57 | X31: ='AutoZ data'!H49 -> 58 | Y31: ='AutoZ data'!H48 -> 57 | Z31: ='AutoZ data'!H47 -> 60 | AA31: ='AutoZ data'!H46 -> 6253 | AB31: ='AutoZ data'!H45 -> 59 | AC31: ='AutoZ data'!H44 -> 60 | AD31: ='AutoZ data'!H43 -> 62 | AE31: ='AutoZ data'!H42 -> 60 | AF31: ='AutoZ data'!H41 -> 59 | AG31: ='AutoZ data'!H40 -> 59 | AH31: ='AutoZ data'!H39 -> 59 | AI31: ='AutoZ data'!H38 -> 63 | AJ31: ='AutoZ data'!H37 -> 61 | AK31: ='AutoZ data'!H36 -> 58 | AO31: =AB34 -> 64 | AP31: =T34 -> <= 50 | AQ31: =AD35 -> 55 | AR31: =V35 -> 52 | AS31: =AF36 -> 62 | AT31: =X36 -> 59 | AU31: =AH37 -> 57 | AV31: =Z37 -> 55 | AW31: array ID: 1078-8 | BA31: =K41 -> 64 | BB31: =S41 -> 65 | BC31: =I40 -> 65 | BD31: =Q40 -> 66 | BE31: =G39 -> 61 | BF31: =O39 -> 54 | BG31: =E38 -> 62 | BH31: =M38 -> 59 | BI31: array ID: 1078-26
B32: ='AutoZ data'!AQ92 -> 57 | C32: ='AutoZ data'!AQ93 -> 56 | D32: ='AutoZ data'!AQ94 -> 56 | E32: ='AutoZ data'!AQ95 -> 58 | F32: ='AutoZ data'!AQ96 -> 54 | G32: ='AutoZ data'!AQ97 -> 55 | H32: ='AutoZ data'!AV2 -> <= 50 | I32: ='AutoZ data'!AV3 -> 53 | J32: ='AutoZ data'!AV4 -> 50 | K32: ='AutoZ data'!AV5 -> 61 | L32: ='AutoZ data'!AV6 -> 52 | M32: ='AutoZ data'!AV7 -> <= 50 | N32: ='AutoZ data'!AV8 -> 122 | O32: ='AutoZ data'!AV9 -> 56 | P32: ='AutoZ data'!AV10 -> <= 50 | Q32: ='AutoZ data'!AV11 -> <= 50 | R32: ='AutoZ data'!AV12 -> 51 | S32: ='AutoZ data'!AV13 -> <= 50 | T32: ='AutoZ data'!H71 -> 51 | U32: ='AutoZ data'!H70 -> 57 | V32: ='AutoZ data'!H69 -> 52 | W32: ='AutoZ data'!H68 -> 59 | X32: ='AutoZ data'!H67 -> 56 | Y32: ='AutoZ data'!H66 -> 2206 | Z32: ='AutoZ data'!H65 -> 56 | AA32: ='AutoZ data'!H64 -> 60 | AB32: ='AutoZ data'!H63 -> 64 | AC32: ='AutoZ data'!H62 -> 60 | AD32: ='AutoZ data'!H61 -> 56 | AE32: ='AutoZ data'!H60 -> 61 | AF32: ='AutoZ data'!H59 -> 59 | AG32: ='AutoZ data'!H58 -> 57 | AH32: ='AutoZ data'!H57 -> 61 | AI32: ='AutoZ data'!H56 -> 59 | AJ32: ='AutoZ data'!H55 -> 60 | AK32: ='AutoZ data'!H54 -> 60 | AO32: =AA34 -> 387 | AP32: =AK35 -> 58 | AQ32: =AC35 -> 56 | AR32: =U35 -> 59 | AS32: =AE36 -> 61 | AT32: =W36 -> 60 | AU32: =AG37 -> 57 | AV32: =Y37 -> 55 | BA32: =L41 -> 63 | BB32: =B40 -> 65 | BC32: =J40 -> 64 | BD32: =R40 -> 66 | BE32: =H39 -> 64 | BF32: =P39 -> 64 | BG32: =F38 -> 60 | BH32: =N38 -> 64
B33: ='AutoZ data'!AQ74 -> 54 | C33: ='AutoZ data'!AQ75 -> 51 | D33: ='AutoZ data'!AQ76 -> 57 | E33: ='AutoZ data'!AQ77 -> 54 | F33: ='AutoZ data'!AQ78 -> 57 | G33: ='AutoZ data'!AQ79 -> 53 | H33: ='AutoZ data'!AQ80 -> 56 | I33: ='AutoZ data'!AQ81 -> 54 | J33: ='AutoZ data'!AQ82 -> 52 | K33: ='AutoZ data'!AQ83 -> 56 | L33: ='AutoZ data'!AQ84 -> 53 | M33: ='AutoZ data'!AQ85 -> 56 | N33: ='AutoZ data'!AQ86 -> 57 | O33: ='AutoZ data'!AQ87 -> 54 | P33: ='AutoZ data'!AQ88 -> 53 | Q33: ='AutoZ data'!AQ89 -> 54 | R33: ='AutoZ data'!AQ90 -> 54 | S33: ='AutoZ data'!AQ91 -> 55 | T33: ='AutoZ data'!H89 -> 4953 | U33: ='AutoZ data'!H88 -> <= 50 | V33: ='AutoZ data'!H87 -> 54 | W33: ='AutoZ data'!H86 -> 57 | X33: ='AutoZ data'!H85 -> 56 | Y33: ='AutoZ data'!H84 -> 55 | Z33: ='AutoZ data'!H83 -> 58 | AA33: ='AutoZ data'!H82 -> 55 | AB33: ='AutoZ data'!H81 -> 54 | AC33: ='AutoZ data'!H80 -> <= 50 | AD33: ='AutoZ data'!H79 -> 53 | AE33: ='AutoZ data'!H78 -> 59 | AF33: ='AutoZ data'!H77 -> 52 | AG33: ='AutoZ data'!H76 -> 59 | AH33: ='AutoZ data'!H75 -> <= 50 | AI33: ='AutoZ data'!H74 -> 57 | AJ33: ='AutoZ data'!H73 -> 52 | AK33: ='AutoZ data'!H72 -> 58 | AO33: =Z34 -> 62 | AP33: =AJ35 -> <= 50 | AQ33: =AB35 -> 51 | AR33: =T35 -> <= 50 | AS33: =AD36 -> 62 | AT33: =V36 -> 59 | AU33: =AF37 -> 63 | AV33: =X37 -> 54 | BA33: =M41 -> 65 | BB33: =C40 -> 64 | BC33: =K40 -> 70 | BD33: =S40 -> 62 | BE33: =I39 -> 56 | BF33: =Q39 -> 58 | BG33: =G38 -> 61 | BH33: =O38 -> 61
B34: ='AutoZ data'!AQ56 -> 56 | C34: ='AutoZ data'!AQ57 -> 60 | D34: ='AutoZ data'!AQ58 -> 58 | E34: ='AutoZ data'!AQ59 -> 58 | F34: ='AutoZ data'!AQ60 -> 79 | G34: ='AutoZ data'!AQ61 -> 5373 | H34: ='AutoZ data'!AQ62 -> 54 | I34: ='AutoZ data'!AQ63 -> 58 | J34: ='AutoZ data'!AQ64 -> 64 | K34: ='AutoZ data'!AQ65 -> 61 | L34: ='AutoZ data'!AQ66 -> 2246 | M34: ='AutoZ data'!AQ67 -> 3849 | N34: ='AutoZ data'!AQ68 -> 57 | O34: ='AutoZ data'!AQ69 -> <=50 | P34: ='AutoZ data'!AQ70 -> 54 | Q34: ='AutoZ data'!AQ71 -> 53 | R34: ='AutoZ data'!AQ72 -> 3293 | S34: ='AutoZ data'!AQ73 -> 51 | T34: ='AutoZ data'!M11 -> <= 50 | U34: ='AutoZ data'!M10 -> 58 | V34: ='AutoZ data'!M9 -> 314 | W34: ='AutoZ data'!M8 -> 51 | X34: ='AutoZ data'!M7 -> <= 50 | Y34: ='AutoZ data'!M6 -> 56 | Z34: ='AutoZ data'!M5 -> 62 | AA34: ='AutoZ data'!M4 -> 387 | AB34: ='AutoZ data'!M3 -> 64 | AC34: ='AutoZ data'!M2 -> 59 | AD34: ='AutoZ data'!H97 -> 51 | AE34: ='AutoZ data'!H96 -> 53 | AF34: ='AutoZ data'!H95 -> 54 | AG34: ='AutoZ data'!H94 -> 55 | AH34: ='AutoZ data'!H93 -> 57 | AI34: ='AutoZ data'!H92 -> 58 | AJ34: ='AutoZ data'!H91 -> 53 | AK34: ='AutoZ data'!H90 -> 57 | AO34: =Y34 -> 56 | AP34: =AI35 -> 51 | AQ34: =AA35 -> 58 | AR34: =AK36 -> 56 | AS34: =AC36 -> 64 | AT34: =U36 -> 61 | AU34: =AE37 -> 58 | AV34: =W37 -> 55 | BA34: =N41 -> 67 | BB34: =D40 -> 67 | BC34: =L40 -> 66 | BD34: =B39 -> 66 | BE34: =J39 -> 64 | BF34: =R39 -> 65 | BG34: =H38 -> 64 | BH34: =P38 -> 60
B35: ='AutoZ data'!AQ38 -> 59 | C35: ='AutoZ data'!AQ39 -> 55 | D35: ='AutoZ data'!AQ40 -> 57 | E35: ='AutoZ data'!AQ41 -> 56 | F35: ='AutoZ data'!AQ42 -> 60 | G35: ='AutoZ data'!AQ43 -> 56 | H35: ='AutoZ data'!AQ44 -> 58 | I35: ='AutoZ data'!AQ45 -> 54 | J35: ='AutoZ data'!AQ46 -> 60 | K35: ='AutoZ data'!AQ47 -> 58 | L35: ='AutoZ data'!AQ48 -> 57 | M35: ='AutoZ data'!AQ49 -> 55 | N35: ='AutoZ data'!AQ50 -> 57 | O35: ='AutoZ data'!AQ51 -> 55 | P35: ='AutoZ data'!AQ52 -> 54 | Q35: ='AutoZ data'!AQ53 -> 58 | R35: ='AutoZ data'!AQ54 -> 57 | S35: ='AutoZ data'!AQ55 -> 56 | T35: ='AutoZ data'!M29 -> <= 50 | U35: ='AutoZ data'!M28 -> 59 | V35: ='AutoZ data'!M27 -> 52 | W35: ='AutoZ data'!M26 -> 54 | X35: ='AutoZ data'!M25 -> 54 | Y35: ='AutoZ data'!M24 -> 57 | Z35: ='AutoZ data'!M23 -> <= 50 | AA35: ='AutoZ data'!M22 -> 58 | AB35: ='AutoZ data'!M21 -> 51 | AC35: ='AutoZ data'!M20 -> 56 | AD35: ='AutoZ data'!M19 -> 55 | AE35: ='AutoZ data'!M18 -> 56 | AF35: ='AutoZ data'!M17 -> 57 | AG35: ='AutoZ data'!M16 -> 51 | AH35: ='AutoZ data'!M15 -> 55 | AI35: ='AutoZ data'!M14 -> 51 | AJ35: ='AutoZ data'!M13 -> <= 50 | AK35: ='AutoZ data'!M12 -> 58 | AO35: =X34 -> <= 50 | AP35: =AH35 -> 55 | AQ35: =Z35 -> <= 50 | AR35: =AJ36 -> 50 | AS35: =AB36 -> 59 | AT35: =T36 -> 63 | AU35: =AD37 -> 61 | AV35: =V37 -> 62 | BA35: =O41 -> 63 | BB35: =E40 -> 68 | BC35: =M40 -> 66 | BD35: =C39 -> 69 | BE35: =K39 -> 56 | BF35: =S39 -> 59 | BG35: =I38 -> 61 | BH35: =Q38 -> 60
B36: ='AutoZ data'!AQ20 -> 50 | C36: ='AutoZ data'!AQ21 -> 52 | D36: ='AutoZ data'!AQ22 -> 52 | E36: ='AutoZ data'!AQ23 -> <= 50 | F36: ='AutoZ data'!AQ24 -> 142 | G36: ='AutoZ data'!AQ25 -> 54 | H36: ='AutoZ data'!AQ26 -> 54 | I36: ='AutoZ data'!AQ27 -> 50 | J36: ='AutoZ data'!AQ28 -> 53 | K36: ='AutoZ data'!AQ29 -> 52 | L36: ='AutoZ data'!AQ30 -> <= 50 | M36: ='AutoZ data'!AQ31 -> 51 | N36: ='AutoZ data'!AQ32 -> <= 50 | O36: ='AutoZ data'!AQ33 -> 56 | P36: ='AutoZ data'!AQ34 -> 57 | Q36: ='AutoZ data'!AQ35 -> 58 | R36: ='AutoZ data'!AQ36 -> 55 | S36: ='AutoZ data'!AQ37 -> 57 | T36: ='AutoZ data'!M47 -> 63 | U36: ='AutoZ data'!M46 -> 61 | V36: ='AutoZ data'!M45 -> 59 | W36: ='AutoZ data'!M44 -> 60 | X36: ='AutoZ data'!M43 -> 59 | Y36: ='AutoZ data'!M42 -> 58 | Z36: ='AutoZ data'!M41 -> 60 | AA36: ='AutoZ data'!M40 -> 61 | AB36: ='AutoZ data'!M39 -> 59 | AC36: ='AutoZ data'!M38 -> 64 | AD36: ='AutoZ data'!M37 -> 62 | AE36: ='AutoZ data'!M36 -> 61 | AF36: ='AutoZ data'!M35 -> 62 | AG36: ='AutoZ data'!M34 -> 57 | AH36: ='AutoZ data'!M33 -> 52 | AI36: ='AutoZ data'!M32 -> 52 | AJ36: ='AutoZ data'!M31 -> 50 | AK36: ='AutoZ data'!M30 -> 56 | AO36: =W34 -> 51 | AP36: =AG35 -> 51 | AQ36: =Y35 -> 57 | AR36: =AI36 -> 52 | AS36: =AA36 -> 61 | AT36: =AK37 -> 59 | AU36: =AC37 -> 55 | AV36: =U37 -> 62 | BA36: =P41 -> 65 | BB36: =F40 -> 64 | BC36: =N40 -> 64 | BD36: =D39 -> 65 | BE36: =L39 -> 63 | BF36: =B38 -> 64 | BG36: =J38 -> 58 | BH36: =R38 -> 59
B37: ='AutoZ data'!AQ2 -> 52 | C37: ='AutoZ data'!AQ3 -> 57 | D37: ='AutoZ data'!AQ4 -> 54 | E37: ='AutoZ data'!AQ5 -> 66 | F37: ='AutoZ data'!AQ6 -> 61 | G37: ='AutoZ data'!AQ7 -> <= 50 | H37: ='AutoZ data'!AQ8 -> 51 | I37: ='AutoZ data'!AQ9 -> 70 | J37: ='AutoZ data'!AQ10 -> 52 | K37: ='AutoZ data'!AQ11 -> 52 | L37: ='AutoZ data'!AQ12 -> 54 | M37: ='AutoZ data'!AQ13 -> <= 50 | N37: ='AutoZ data'!AQ14 -> <= 50 | O37: ='AutoZ data'!AQ15 -> 79 | P37: ='AutoZ data'!AQ16 -> 52 | Q37: ='AutoZ data'!AQ17 -> 57 | R37: ='AutoZ data'!AQ18 -> 53 | S37: ='AutoZ data'!AQ19 -> 51 | T37: ='AutoZ data'!M65 -> 60 | U37: ='AutoZ data'!M64 -> 62 | V37: ='AutoZ data'!M63 -> 62 | W37: ='AutoZ data'!M62 -> 55 | X37: ='AutoZ data'!M61 -> 54 | Y37: ='AutoZ data'!M60 -> 55 | Z37: ='AutoZ data'!M59 -> 55 | AA37: ='AutoZ data'!M58 -> 59 | AB37: ='AutoZ data'!M57 -> 57 | AC37: ='AutoZ data'!M56 -> 55 | AD37: ='AutoZ data'!M55 -> 61 | AE37: ='AutoZ data'!M54 -> 58 | AF37: ='AutoZ data'!M53 -> 63 | AG37: ='AutoZ data'!M52 -> 57 | AH37: ='AutoZ data'!M51 -> 57 | AI37: ='AutoZ data'!M50 -> 60 | AJ37: ='AutoZ data'!M49 -> 57 | AK37: ='AutoZ data'!M48 -> 59 | AL37: wire | AO37: =V34 -> 314 | AP37: =AF35 -> 57 | AQ37: =X35 -> 54 | AR37: =AH36 -> 52 | AS37: =Z36 -> 60 | AT37: =AJ37 -> 57 | AU37: =AB37 -> 57 | AV37: =T37 -> 60 | BA37: =Q41 -> 64 | BB37: =G40 -> 62 | BC37: =O40 -> 66 | BD37: =E39 -> 62 | BE37: =M39 -> 59 | BF37: =C38 -> 59 | BG37: =K38 -> 62 | BH37: =S38 -> 56
B38: ='AutoZ data'!AL80 -> 64 | C38: ='AutoZ data'!AL81 -> 59 | D38: ='AutoZ data'!AL82 -> 60 | E38: ='AutoZ data'!AL83 -> 62 | F38: ='AutoZ data'!AL84 -> 60 | G38: ='AutoZ data'!AL85 -> 61 | H38: ='AutoZ data'!AL86 -> 64 | I38: ='AutoZ data'!AL87 -> 61 | J38: ='AutoZ data'!AL88 -> 58 | K38: ='AutoZ data'!AL89 -> 62 | L38: ='AutoZ data'!AL90 -> 61 | M38: ='AutoZ data'!AL91 -> 59 | N38: ='AutoZ data'!AL92 -> 64 | O38: ='AutoZ data'!AL93 -> 61 | P38: ='AutoZ data'!AL94 -> 60 | Q38: ='AutoZ data'!AL95 -> 60 | R38: ='AutoZ data'!AL96 -> 59 | S38: ='AutoZ data'!AL97 -> 56 | T38: ='AutoZ data'!M83 -> 53 | U38: ='AutoZ data'!M82 -> 64 | V38: ='AutoZ data'!M81 -> 57 | W38: ='AutoZ data'!M80 -> 58 | X38: ='AutoZ data'!M79 -> 56 | Y38: ='AutoZ data'!M78 -> 53 | Z38: ='AutoZ data'!M77 -> 54 | AA38: ='AutoZ data'!M76 -> 55 | AB38: ='AutoZ data'!M75 -> 62 | AC38: ='AutoZ data'!M74 -> 385 | AD38: ='AutoZ data'!M73 -> 53 | AE38: ='AutoZ data'!M72 -> 59 | AF38: ='AutoZ data'!M71 -> 53 | AG38: ='AutoZ data'!M70 -> 57 | AH38: ='AutoZ data'!M69 -> 74 | AI38: ='AutoZ data'!M68 -> 63 | AJ38: ='AutoZ data'!M67 -> 53 | AK38: ='AutoZ data'!M66 -> 1530 | AL38: bundle
B39: ='AutoZ data'!AL62 -> 66 | C39: ='AutoZ data'!AL63 -> 69 | D39: ='AutoZ data'!AL64 -> 65 | E39: ='AutoZ data'!AL65 -> 62 | F39: ='AutoZ data'!AL66 -> 1459 | G39: ='AutoZ data'!AL67 -> 61 | H39: ='AutoZ data'!AL68 -> 64 | I39: ='AutoZ data'!AL69 -> 56 | J39: ='AutoZ data'!AL70 -> 64 | K39: ='AutoZ data'!AL71 -> 56 | L39: ='AutoZ data'!AL72 -> 63 | M39: ='AutoZ data'!AL73 -> 59 | N39: ='AutoZ data'!AL74 -> 61 | O39: ='AutoZ data'!AL75 -> 54 | P39: ='AutoZ data'!AL76 -> 64 | Q39: ='AutoZ data'!AL77 -> 58 | R39: ='AutoZ data'!AL78 -> 65 | S39: ='AutoZ data'!AL79 -> 59 | T39: ='AutoZ data'!R5 -> 63 | U39: ='AutoZ data'!R4 -> 62 | V39: ='AutoZ data'!R3 -> 55 | W39: ='AutoZ data'!R2 -> 74 | X39: ='AutoZ data'!M97 -> 58 | Y39: ='AutoZ data'!M96 -> 57 | Z39: ='AutoZ data'!M95 -> 60 | AA39: ='AutoZ data'!M94 -> 58 | AB39: ='AutoZ data'!M93 -> 59 | AC39: ='AutoZ data'!M92 -> 58 | AD39: ='AutoZ data'!M91 -> 68 | AE39: ='AutoZ data'!M90 -> 58 | AF39: ='AutoZ data'!M89 -> 60 | AG39: ='AutoZ data'!M88 -> 60 | AH39: ='AutoZ data'!M87 -> 56 | AI39: ='AutoZ data'!M86 -> 61 | AJ39: ='AutoZ data'!M85 -> 59 | AK39: ='AutoZ data'!M84 -> 53 | AO39: =AK38 -> 1530 | AP39: =AC38 -> 385 | AQ39: =U38 -> 64 | AR39: =AE39 -> 58 | AS39: =W39 -> 74 | AT39: =AG40 -> 77 | AU39: =Y40 -> <= 50 | AV39: =AI41 -> 342 | AW39: A5 | BA39: =B37 -> 52 | BB39: =J37 -> 52 | BC39: =R37 -> 53 | BD39: =H36 -> 54 | BE39: =P36 -> 57 | BF39: =F35 -> 60 | BG39: =N35 -> 57 | BH39: =D34 -> 58 | BI39: A13
B40: ='AutoZ data'!AL44 -> 65 | C40: ='AutoZ data'!AL45 -> 64 | D40: ='AutoZ data'!AL46 -> 67 | E40: ='AutoZ data'!AL47 -> 68 | F40: ='AutoZ data'!AL48 -> 64 | G40: ='AutoZ data'!AL49 -> 62 | H40: ='AutoZ data'!AL50 -> 64 | I40: ='AutoZ data'!AL51 -> 65 | J40: ='AutoZ data'!AL52 -> 64 | K40: ='AutoZ data'!AL53 -> 70 | L40: ='AutoZ data'!AL54 -> 66 | M40: ='AutoZ data'!AL55 -> 66 | N40: ='AutoZ data'!AL56 -> 64 | O40: ='AutoZ data'!AL57 -> 66 | P40: ='AutoZ data'!AL58 -> 63 | Q40: ='AutoZ data'!AL59 -> 66 | R40: ='AutoZ data'!AL60 -> 66 | S40: ='AutoZ data'!AL61 -> 62 | T40: ='AutoZ data'!R23 -> <= 50 | U40: ='AutoZ data'!R22 -> 61 | V40: ='AutoZ data'!R21 -> 53 | W40: ='AutoZ data'!R20 -> 59 | X40: ='AutoZ data'!R19 -> <= 50 | Y40: ='AutoZ data'!R18 -> <= 50 | Z40: ='AutoZ data'!R17 -> 60 | AA40: ='AutoZ data'!R16 -> <= 50 | AB40: ='AutoZ data'!R15 -> 59 | AC40: ='AutoZ data'!R14 -> 56 | AD40: ='AutoZ data'!R13 -> 52 | AE40: ='AutoZ data'!R12 -> 62 | AF40: ='AutoZ data'!R11 -> 50 | AG40: ='AutoZ data'!R10 -> 77 | AH40: ='AutoZ data'!R9 -> 57 | AI40: ='AutoZ data'!R8 -> 58 | AJ40: ='AutoZ data'!R7 -> <= 50 | AK40: ='AutoZ data'!R6 -> 61 | AO40: =AJ38 -> 53 | AP40: =AB38 -> 62 | AQ40: =T38 -> 53 | AR40: =AD39 -> 68 | AS40: =V39 -> 55 | AT40: =AF40 -> 50 | AU40: =X40 -> <= 50 | AV40: =AH41 -> 58 | AW40: array ID: 1078-9 | BA40: =C37 -> 57 | BB40: =K37 -> 52 | BC40: =S37 -> 51 | BD40: =I36 -> 50 | BE40: =Q36 -> 58 | BF40: =G35 -> 56 | BG40: =O35 -> 55 | BH40: =E34 -> 58 | BI40: array ID: 1078-27
B41: ='AutoZ data'!AL26 -> 61 | C41: ='AutoZ data'!AL27 -> 55 | D41: ='AutoZ data'!AL28 -> 63 | E41: ='AutoZ data'!AL29 -> 52 | F41: ='AutoZ data'!AL30 -> 57 | G41: ='AutoZ data'!AL31 -> 51 | H41: ='AutoZ data'!AL32 -> 52 | I41: ='AutoZ data'!AL33 -> 54 | J41: ='AutoZ data'!AL34 -> 60 | K41: ='AutoZ data'!AL35 -> 64 | L41: ='AutoZ data'!AL36 -> 63 | M41: ='AutoZ data'!AL37 -> 65 | N41: ='AutoZ data'!AL38 -> 67 | O41: ='AutoZ data'!AL39 -> 63 | P41: ='AutoZ data'!AL40 -> 65 | Q41: ='AutoZ data'!AL41 -> 64 | R41: ='AutoZ data'!AL42 -> 63 | S41: ='AutoZ data'!AL43 -> 65 | T41: ='AutoZ data'!R41 -> 57 | U41: ='AutoZ data'!R40 -> 63 | V41: ='AutoZ data'!R39 -> 61 | W41: ='AutoZ data'!R38 -> 64 | X41: ='AutoZ data'!R37 -> 65 | Y41: ='AutoZ data'!R36 -> 193 | Z41: ='AutoZ data'!R35 -> <= 50 | AA41: ='AutoZ data'!R34 -> 75 | AB41: ='AutoZ data'!R33 -> 52 | AC41: ='AutoZ data'!R32 -> 56 | AD41: ='AutoZ data'!R31 -> 53 | AE41: ='AutoZ data'!R30 -> 59 | AF41: ='AutoZ data'!R29 -> <=50 | AG41: ='AutoZ data'!R28 -> 57 | AH41: ='AutoZ data'!R27 -> 58 | AI41: ='AutoZ data'!R26 -> 342 | AJ41: ='AutoZ data'!R25 -> 56 | AK41: ='AutoZ data'!R24 -> 62 | AO41: =AI38 -> 63 | AP41: =AA38 -> 55 | AQ41: =AK39 -> 53 | AR41: =AC39 -> 58 | AS41: =U39 -> 62 | AT41: =AE40 -> 62 | AU41: =W40 -> 59 | AV41: =AG41 -> 57 | BA41: =D37 -> 54 | BB41: =L37 -> 54 | BC41: =B36 -> 50 | BD41: =J36 -> 53 | BE41: =R36 -> 55 | BF41: =H35 -> 58 | BG41: =P35 -> 54 | BH41: =F34 -> 79
B42: ='AutoZ data'!AL8 -> 54 | C42: ='AutoZ data'!AL9 -> 55 | D42: ='AutoZ data'!AL10 -> 62 | E42: ='AutoZ data'!AL11 -> 53 | F42: ='AutoZ data'!AL12 -> 64 | G42: ='AutoZ data'!AL13 -> 52 | H42: ='AutoZ data'!AL14 -> 55 | I42: ='AutoZ data'!AL15 -> 59 | J42: ='AutoZ data'!AL16 -> 55 | K42: ='AutoZ data'!AL17 -> 57 | L42: ='AutoZ data'!AL18 -> 60 | M42: ='AutoZ data'!AL19 -> 58 | N42: ='AutoZ data'!AL20 -> 61 | O42: ='AutoZ data'!AL21 -> 53 | P42: ='AutoZ data'!AL22 -> 61 | Q42: ='AutoZ data'!AL23 -> <= 50 | R42: ='AutoZ data'!AL24 -> 61 | S42: ='AutoZ data'!AL25 -> 55 | T42: ='AutoZ data'!R59 -> 67 | U42: ='AutoZ data'!R58 -> 62 | V42: ='AutoZ data'!R57 -> 67 | W42: ='AutoZ data'!R56 -> 66 | X42: ='AutoZ data'!R55 -> 68 | Y42: ='AutoZ data'!R54 -> 67 | Z42: ='AutoZ data'!R53 -> 72 | AA42: ='AutoZ data'!R52 -> 63 | AB42: ='AutoZ data'!R51 -> 65 | AC42: ='AutoZ data'!R50 -> 63 | AD42: ='AutoZ data'!R49 -> 63 | AE42: ='AutoZ data'!R48 -> 64 | AF42: ='AutoZ data'!R47 -> 67 | AG42: ='AutoZ data'!R46 -> 68 | AH42: ='AutoZ data'!R45 -> 65 | AI42: ='AutoZ data'!R44 -> 66 | AJ42: ='AutoZ data'!R43 -> 64 | AK42: ='AutoZ data'!R42 -> 63 | AO42: =AH38 -> 74 | AP42: =Z38 -> 54 | AQ42: =AJ39 -> 59 | AR42: =AB39 -> 59 | AS42: =T39 -> 63 | AT42: =AD40 -> 52 | AU42: =V40 -> 53 | AV42: =AF41 -> <=50 | BA42: =E37 -> 66 | BB42: =M37 -> <= 50 | BC42: =C36 -> 52 | BD42: =K36 -> 52 | BE42: =S36 -> 57 | BF42: =I35 -> 54 | BG42: =Q35 -> 58 | BH42: =G34 -> 5373
...

Sheet AutoZ data
A1: Table1 1-96 J1-J2-J3 | B1: NSP channel # | C1: Input Auto Z here | D1: Array Elec# | F1: Table2 97-192 J4-J5-J6 | G1: NSP channel # | H1: Input Auto Z here | I1: Array Elec# | K1: Table3 193-288 J7-J8-J9 | L1: NSP channel # | M1: Input Auto Z here | N1: Array Elec# | P1: Table4 289-384 J10-J11-J12 | Q1: NSP channel # | R1: Input Auto Z here | S1: Array Elec# | U1: Table5 385-480 J13-J14-J15 | V1: NSP channel # | W1: Input Auto Z here | X1: Array Elec# | Z1: Table6 481-576 J16-J17-J18 | AA1: NSP channel # | AB1: Input Auto Z here | AC1: Array Elec# | AE1: Table7 577-672 J19-J20-J21 | AF1: NSP channel # | AG1: Input Auto Z here | AH1: Array Elec# | AJ1: Table8 673-768 J22-J23-J24 | AK1: NSP channel # | AL1: Input Auto Z here | AM1: Array Elec# | AO1: Table9 769-864 J25-J26-J27 | AP1: NSP channel # | AQ1: Input Auto Z here | AR1: Array Elec# | AT1: Table10 865-960 J28-J29-J30 | AU1: NSP channel # | AV1: Input Auto Z here | AW1: Array Elec# | AY1: Table11 961-1024 J31-J32 | AZ1: NSP channel # | BA1: Input Auto Z here | BB1: Array Elec#
B2: chan1 | C2: 562 | D2: 1 | G2: chan97 | H2: 54 | I2: 97 | L2: chan193 | M2: 59 | N2: 193 | Q2: chan289 | R2: 74 | S2: 289 | V2: chan385 | W2: 59 | X2: 385 | AA2: chan481 | AB2: 58 | AC2: 481 | AF2: chan577 | AG2: 57 | AH2: 577 | AK2: chan673 | AL2: 60 | AM2: 673 | AP2: chan769 | AQ2: 52 | AR2: 769 | AU2: chan865 | AV2: <= 50 | AW2: 865 | AZ2: chan961 | BA2: <= 50 | BB2: 961
B3: chan2 | C3: 8290 | D3: 2 | G3: chan98 | H3: 56 | I3: 98 | L3: chan194 | M3: 64 | N3: 194 | Q3: chan290 | R3: 55 | S3: 290 | V3: chan386 | W3: 61 | X3: 386 | AA3: chan482 | AB3: 61 | AC3: 482 | AF3: chan578 | AG3: 60 | AH3: 578 | AK3: chan674 | AL3: 62 | AM3: 674 | AP3: chan770 | AQ3: 57 | AR3: 770 | AU3: chan866 | AV3: 53 | AW3: 866 | AZ3: chan962 | BA3: 59 | BB3: 962
B4: chan3 | C4: 55 | D4: 3 | G4: chan99 | H4: 56 | I4: 99 | L4: chan195 | M4: 387 | N4: 195 | Q4: chan291 | R4: 62 | S4: 291 | V4: chan387 | W4: 57 | X4: 387 | AA4: chan483 | AB4: 61 | AC4: 483 | AF4: chan579 | AG4: 60 | AH4: 579 | AK4: chan675 | AL4: 63 | AM4: 675 | AP4: chan771 | AQ4: 54 | AR4: 771 | AU4: chan867 | AV4: 50 | AW4: 867 | AZ4: chan963 | BA4: 60 | BB4: 963
B5: chan4 | C5: 59 | D5: 4 | G5: chan100 | H5: 58 | I5: 100 | L5: chan196 | M5: 62 | N5: 196 | Q5: chan292 | R5: 63 | S5: 292 | V5: chan388 | W5: 60 | X5: 388 | AA5: chan484 | AB5: 79 | AC5: 484 | AF5: chan580 | AG5: 66 | AH5: 580 | AK5: chan676 | AL5: 64 | AM5: 676 | AP5: chan772 | AQ5: 66 | AR5: 772 | AU5: chan868 | AV5: 61 | AW5: 868 | AZ5: chan964 | BA5: 61 | BB5: 964
B6: chan5 | C6: 50 | D6: 5 | G6: chan101 | H6: 50 | I6: 101 | L6: chan197 | M6: 56 | N6: 197 | Q6: chan293 | R6: 61 | S6: 293 | V6: chan389 | W6: 56 | X6: 389 | AA6: chan485 | AB6: 59 | AC6: 485 | AF6: chan581 | AG6: 114 | AH6: 581 | AK6: chan677 | AL6: 61 | AM6: 677 | AP6: chan773 | AQ6: 61 | AR6: 773 | AU6: chan869 | AV6: 52 | AW6: 869 | AZ6: chan965 | BA6: 75 | BB6: 965
B7: chan6 | C7: <= 50 | D7: 6 | G7: chan102 | H7: <= 50 | I7: 102 | L7: chan198 | M7: <= 50 | N7: 198 | Q7: chan294 | R7: <= 50 | S7: 294 | V7: chan390 | W7: <= 50 | X7: 390 | AA7: chan486 | AB7: <= 50 | AC7: 486 | AF7: chan582 | AG7: <= 50 | AH7: 582 | AK7: chan678 | AL7: <= 50 | AM7: 678 | AP7: chan774 | AQ7: <= 50 | AR7: 774 | AU7: chan870 | AV7: <= 50 | AW7: 870 | AZ7: chan966 | BA7: <= 50 | BB7: 966
B8: chan7 | C8: <= 50 | D8: 7 | G8: chan103 | H8: <= 50 | I8: 103 | L8: chan199 | M8: 51 | N8: 199 | Q8: chan295 | R8: 58 | S8: 295 | V8: chan391 | W8: <= 50 | X8: 391 | AA8: chan487 | AB8: 55 | AC8: 487 | AF8: chan583 | AG8: <= 50 | AH8: 583 | AK8: chan679 | AL8: 54 | AM8: 679 | AP8: chan775 | AQ8: 51 | AR8: 775 | AU8: chan871 | AV8: 122 | AW8: 871 | AZ8: chan967 | BA8: 390 | BB8: 967
B9: chan8 | C9: 50 | D9: 8 | G9: chan104 | H9: 51 | I9: 104 | L9: chan200 | M9: 314 | N9: 200 | Q9: chan296 | R9: 57 | S9: 296 | V9: chan392 | W9: 57 | X9: 392 | AA9: chan488 | AB9: 57 | AC9: 488 | AF9: chan584 | AG9: 65 | AH9: 584 | AK9: chan680 | AL9: 55 | AM9: 680 | AP9: chan776 | AQ9: 70 | AR9: 776 | AU9: chan872 | AV9: 56 | AW9: 872 | AZ9: chan968 | BA9: 57 | BB9: 968
B10: chan9 | C10: 951 | D10: 9 | G10: chan105 | H10: 57 | I10: 105 | L10: chan201 | M10: 58 | N10: 201 | Q10: chan297 | R10: 77 | S10: 297 | V10: chan393 | W10: 62 | X10: 393 | AA10: chan489 | AB10: 61 | AC10: 489 | AF10: chan585 | AG10: 59 | AH10: 585 | AK10: chan681 | AL10: 62 | AM10: 681 | AP10: chan777 | AQ10: 52 | AR10: 777 | AU10: chan873 | AV10: <= 50 | AW10: 873 | AZ10: chan969 | BA10: 59 | BB10: 969
B11: chan10 | C11: 61 | D11: 10 | G11: chan106 | H11: <= 50 | I11: 106 | L11: chan202 | M11: <= 50 | N11: 202 | Q11: chan298 | R11: 50 | S11: 298 | V11: chan394 | W11: 52 | X11: 394 | AA11: chan490 | AB11: 52 | AC11: 490 | AF11: chan586 | AG11: 52 | AH11: 586 | AK11: chan682 | AL11: 53 | AM11: 682 | AP11: chan778 | AQ11: 52 | AR11: 778 | AU11: chan874 | AV11: <= 50 | AW11: 874 | AZ11: chan970 | BA11: 51 | BB11: 970
B12: chan11 | C12: 58 | D12: 11 | G12: chan107 | H12: 58 | I12: 107 | L12: chan203 | M12: 58 | N12: 203 | Q12: chan299 | R12: 62 | S12: 299 | V12: chan395 | W12: 64 | X12: 395 | AA12: chan491 | AB12: 63 | AC12: 491 | AF12: chan587 | AG12: 59 | AH12: 587 | AK12: chan683 | AL12: 64 | AM12: 683 | AP12: chan779 | AQ12: 54 | AR12: 779 | AU12: chan875 | AV12: 51 | AW12: 875 | AZ12: chan971 | BA12: 62 | BB12: 971
B13: chan12 | C13: <= 50 | D13: 12 | G13: chan108 | H13: <= 50 | I13: 108 | L13: chan204 | M13: <= 50 | N13: 204 | Q13: chan300 | R13: 52 | S13: 300 | V13: chan396 | W13: <= 50 | X13: 396 | AA13: chan492 | AB13: 51 | AC13: 492 | AF13: chan588 | AG13: 51 | AH13: 588 | AK13: chan684 | AL13: 52 | AM13: 684 | AP13: chan780 | AQ13: <= 50 | AR13: 780 | AU13: chan876 | AV13: <= 50 | AW13: 876 | AZ13: chan972 | BA13: 51 | BB13: 972
B14: chan13 | C14: <= 50 | D14: 13 | G14: chan109 | H14: <= 50 | I14: 109 | L14: chan205 | M14: 51 | N14: 205 | Q14: chan301 | R14: 56 | S14: 301 | V14: chan397 | W14: 55 | X14: 397 | AA14: chan493 | AB14: 54 | AC14: 493 | AF14: chan589 | AG14: 54 | AH14: 589 | AK14: chan685 | AL14: 55 | AM14: 685 | AP14: chan781 | AQ14: <= 50 | AR14: 781 | AU14: chan877 | AV14: <= 50 | AW14: 877 | AZ14: chan973 | BA14: 55 | BB14: 973
B15: chan14 | C15: <= 50 | D15: 14 | G15: chan110 | H15: 51 | I15: 110 | L15: chan206 | M15: 55 | N15: 206 | Q15: chan302 | R15: 59 | S15: 302 | V15: chan398 | W15: 57 | X15: 398 | AA15: chan494 | AB15: 58 | AC15: 494 | AF15: chan590 | AG15: 60 | AH15: 590 | AK15: chan686 | AL15: 59 | AM15: 686 | AP15: chan782 | AQ15: 79 | AR15: 782 | AU15: chan878 | AV15: 56 | AW15: 878 | AZ15: chan974 | BA15: 61 | BB15: 974
B16: chan15 | C16: <= 50 | D16: 15 | G16: chan111 | H16: <= 50 | I16: 111 | L16: chan207 | M16: 51 | N16: 207 | Q16: chan303 | R16: <= 50 | S16: 303 | V16: chan399 | W16: 51 | X16: 399 | AA16: chan495 | AB16: 55 | AC16: 495 | AF16: chan591 | AG16: 50 | AH16: 591 | AK16: chan687 | AL16: 55 | AM16: 687 | AP16: chan783 | AQ16: 52 | AR16: 783 | AU16: chan879 | AV16: <= 50 | AW16: 879 | AZ16: chan975 | BA16: 58 | BB16: 975
B17: chan16 | C17: 52 | D17: 16 | G17: chan112 | H17: 52 | I17: 112 | L17: chan208 | M17: 57 | N17: 208 | Q17: chan304 | R17: 60 | S17: 304 | V17: chan400 | W17: 114 | X17: 400 | AA17: chan496 | AB17: 58 | AC17: 496 | AF17: chan592 | AG17: 58 | AH17: 592 | AK17: chan688 | AL17: 57 | AM17: 688 | AP17: chan784 | AQ17: 57 | AR17: 784 | AU17: chan880 | AV17: 54 | AW17: 880 | AZ17: chan976 | BA17: 58 | BB17: 976
B18: chan17 | C18: 54 | D18: 17 | G18: chan113 | H18: 56 | I18: 113 | L18: chan209 | M18: 56 | N18: 209 | Q18: chan305 | R18: <= 50 | S18: 305 | V18: chan401 | W18: 62 | X18: 401 | AA18: chan497 | AB18: 59 | AC18: 497 | AF18: chan593 | AG18: 57 | AH18: 593 | AK18: chan689 | AL18: 60 | AM18: 689 | AP18: chan785 | AQ18: 53 | AR18: 785 | AU18: chan881 | AV18: <= 50 | AW18: 881 | AZ18: chan977 | BA18: 59 | BB18: 977
B19: chan18 | C19: 52 | D19: 18 | G19: chan114 | H19: 52 | I19: 114 | L19: chan210 | M19: 55 | N19: 210 | Q19: chan306 | R19: <= 50 | S19: 306 | V19: chan402 | W19: 57 | X19: 402 | AA19: chan498 | AB19: 56 | AC19: 498 | AF19: chan594 | AG19: 55 | AH19: 594 | AK19: chan690 | AL19: 58 | AM19: 690 | AP19: chan786 | AQ19: 51 | AR19: 786 | AU19: chan882 | AV19: <= 50 | AW19: 882 | AZ19: chan978 | BA19: 56 | BB19: 978
B20: chan19 | C20: 58 | D20: 19 | G20: chan115 | H20: 55 | I20: 115 | L20: chan211 | M20: 56 | N20: 211 | Q20: chan307 | R20: 59 | S20: 307 | V20: chan403 | W20: 59 | X20: 403 | AA20: chan499 | AB20: 59 | AC20: 499 | AF20: chan595 | AG20: 58 | AH20: 595 | AK20: chan691 | AL20: 61 | AM20: 691 | AP20: chan787 | AQ20: 50 | AR20: 787 | AU20: chan883 | AV20: <= 50 | AW20: 883 | AZ20: chan979 | BA20: 60 | BB20: 979
B21: chan20 | C21: 50 | D21: 20 | G21: chan116 | H21: <= 50 | I21: 116 | L21: chan212 | M21: 51 | N21: 212 | Q21: chan308 | R21: 53 | S21: 308 | V21: chan404 | W21: 52 | X21: 404 | AA21: chan500 | AB21: 53 | AC21: 500 | AF21: chan596 | AG21: 52 | AH21: 596 | AK21: chan692 | AL21: 53 | AM21: 692 | AP21: chan788 | AQ21: 52 | AR21: 788 | AU21: chan884 | AV21: <= 50 | AW21: 884 | AZ21: chan980 | BA21: 54 | BB21: 980
B22: chan21 | C22: 59 | D22: 21 | G22: chan117 | H22: 54 | I22: 117 | L22: chan213 | M22: 58 | N22: 213 | Q22: chan309 | R22: 61 | S22: 309 | V22: chan405 | W22: 60 | X22: 405 | AA22: chan501 | AB22: 60 | AC22: 501 | AF22: chan597 | AG22: 58 | AH22: 597 | AK22: chan693 | AL22: 61 | AM22: 693 | AP22: chan789 | AQ22: 52 | AR22: 789 | AU22: chan885 | AV22: 51 | AW22: 885 | AZ22: chan981 | BA22: 63 | BB22: 981
B23: chan22 | C23: <= 50 | D23: 22 | G23: chan118 | H23: <= 50 | I23: 118 | L23: chan214 | M23: <= 50 | N23: 214 | Q23: chan310 | R23: <= 50 | S23: 310 | V23: chan406 | W23: <= 50 | X23: 406 | AA23: chan502 | AB23: <= 50 | AC23: 502 | AF23: chan598 | AG23: <= 50 | AH23: 598 | AK23: chan694 | AL23: <= 50 | AM23: 694 | AP23: chan790 | AQ23: <= 50 | AR23: 790 | AU23: chan886 | AV23: <= 50 | AW23: 886 | AZ23: chan982 | BA23: <= 50 | BB23: 982
B24: chan23 | C24: 58 | D24: 23 | G24: chan119 | H24: 55 | I24: 119 | L24: chan215 | M24: 57 | N24: 215 | Q24: chan311 | R24: 62 | S24: 311 | V24: chan407 | W24: 54 | X24: 407 | AA24: chan503 | AB24: 61 | AC24: 503 | AF24: chan599 | AG24: 55 | AH24: 599 | AK24: chan695 | AL24: 61 | AM24: 695 | AP24: chan791 | AQ24: 142 | AR24: 791 | AU24: chan887 | AV24: <= 50 | AW24: 887 | AZ24: chan983 | BA24: 63 | BB24: 983
B25: chan24 | C25: 54 | D25: 24 | G25: chan120 | H25: 51 | I25: 120 | L25: chan216 | M25: 54 | N25: 216 | Q25: chan312 | R25: 56 | S25: 312 | V25: chan408 | W25: 58 | X25: 408 | AA25: chan504 | AB25: 57 | AC25: 504 | AF25: chan600 | AG25: 62 | AH25: 600 | AK25: chan696 | AL25: 55 | AM25: 696 | AP25: chan792 | AQ25: 54 | AR25: 792 | AU25: chan888 | AV25: 51 | AW25: 888 | AZ25: chan984 | BA25: 57 | BB25: 984
B26: chan25 | C26: 61 | D26: 25 | G26: chan121 | H26: 58 | I26: 121 | L26: chan217 | M26: 54 | N26: 217 | Q26: chan313 | R26: 342 | S26: 313 | V26: chan409 | W26: 62 | X26: 409 | AA26: chan505 | AB26: 61 | AC26: 505 | AF26: chan601 | AG26: 62 | AH26: 601 | AK26: chan697 | AL26: 61 | AM26: 697 | AP26: chan793 | AQ26: 54 | AR26: 793 | AU26: chan889 | AV26: <= 50 | AW26: 889 | AZ26: chan985 | BA26: 61 | BB26: 985
B27: chan26 | C27: 52 | D27: 26 | G27: chan122 | H27: 52 | I27: 122 | L27: chan218 | M27: 52 | N27: 218 | Q27: chan314 | R27: 58 | S27: 314 | V27: chan410 | W27: 8317 | X27: 410 | AA27: chan506 | AB27: 55 | AC27: 506 | AF27: chan602 | AG27: 56 | AH27: 602 | AK27: chan698 | AL27: 55 | AM27: 698 | AP27: chan794 | AQ27: 50 | AR27: 794 | AU27: chan890 | AV27: <= 50 | AW27: 890 | AZ27: chan986 | BA27: 55 | BB27: 986
B28: chan27 | C28: 63 | D28: 27 | G28: chan123 | H28: 57 | I28: 123 | L28: chan219 | M28: 59 | N28: 219 | Q28: chan315 | R28: 57 | S28: 315 | V28: chan411 | W28: 61 | X28: 411 | AA28: chan507 | AB28: 62 | AC28: 507 | AF28: chan603 | AG28: 63 | AH28: 603 | AK28: chan699 | AL28: 63 | AM28: 699 | AP28: chan795 | AQ28: 53 | AR28: 795 | AU28: chan891 | AV28: 52 | AW28: 891 | AZ28: chan987 | BA28: 62 | BB28: 987
B29: chan28 | C29: <= 50 | D29: 28 | G29: chan124 | H29: <= 50 | I29: 124 | L29: chan220 | M29: <= 50 | N29: 220 | Q29: chan316 | R29: <=50 | S29: 316 | V29: chan412 | W29: 52 | X29: 412 | AA29: chan508 | AB29: 52 | AC29: 508 | AF29: chan604 | AG29: 52 | AH29: 604 | AK29: chan700 | AL29: 52 | AM29: 700 | AP29: chan796 | AQ29: 52 | AR29: 796 | AU29: chan892 | AV29: <= 50 | AW29: 892 | AZ29: chan988 | BA29: 51 | BB29: 988
B30: chan29 | C30: 60 | D30: 29 | G30: chan125 | H30: 54 | I30: 125 | L30: chan221 | M30: 56 | N30: 221 | Q30: chan317 | R30: 59 | S30: 317 | V30: chan413 | W30: 56 | X30: 413 | AA30: chan509 | AB30: 58 | AC30: 509 | AF30: chan605 | AG30: 59 | AH30: 605 | AK30: chan701 | AL30: 57 | AM30: 701 | AP30: chan797 | AQ30: <= 50 | AR30: 797 | AU30: chan893 | AV30: <= 50 | AW30: 893 | AZ30: chan989 | BA30: 59 | BB30: 989
B31: chan30 | C31: 51 | D31: 30 | G31: chan126 | H31: <= 50 | I31: 126 | L31: chan222 | M31: 50 | N31: 222 | Q31: chan318 | R31: 53 | S31: 318 | V31: chan414 | W31: <= 50 | X31: 414 | AA31: chan510 | AB31: 53 | AC31: 510 | AF31: chan606 | AG31: 53 | AH31: 606 | AK31: chan702 | AL31: 51 | AM31: 702 | AP31: chan798 | AQ31: 51 | AR31: 798 | AU31: chan894 | AV31: <= 50 | AW31: 894 | AZ31: chan990 | BA31: 53 | BB31: 990
B32: chan31 | C32: 54 | D32: 31 | G32: chan127 | H32: 50 | I32: 127 | L32: chan223 | M32: 52 | N32: 223 | Q32: chan319 | R32: 56 | S32: 319 | V32: chan415 | W32: 6905 | X32: 415 | AA32: chan511 | AB32: 56 | AC32: 511 | AF32: chan607 | AG32: 56 | AH32: 607 | AK32: chan703 | AL32: 52 | AM32: 703 | AP32: chan799 | AQ32: <= 50 | AR32: 799 | AU32: chan895 | AV32: <= 50 | AW32: 895 | AZ32: chan991 | BA32: 56 | BB32: 991
B33: chan32 | C33: <= 50 | D33: 32 | G33: chan128 | H33: <= 50 | I33: 128 | L33: chan224 | M33: 52 | N33: 224 | Q33: chan320 | R33: 52 | S33: 320 | V33: chan416 | W33: 64 | X33: 416 | AA33: chan512 | AB33: 54 | AC33: 512 | AF33: chan608 | AG33: 55 | AH33: 608 | AK33: chan704 | AL33: 54 | AM33: 704 | AP33: chan800 | AQ33: 56 | AR33: 800 | AU33: chan896 | AV33: 56 | AW33: 896 | AZ33: chan992 | BA33: 53 | BB33: 992
B34: chan33 | C34: 57 | D34: 33 | G34: chan129 | H34: 54 | I34: 129 | L34: chan225 | M34: 57 | N34: 225 | Q34: chan321 | R34: 75 | S34: 321 | V34: chan417 | W34: 61 | X34: 417 | AA34: chan513 | AB34: 56 | AC34: 513 | AF34: chan609 | AG34: 59 | AH34: 609 | AK34: chan705 | AL34: 60 | AM34: 705 | AP34: chan801 | AQ34: 57 | AR34: 801 | AU34: chan897 | AV34: 52 | AW34: 897 | AZ34: chan993 | BA34: 60 | BB34: 993
B35: chan34 | C35: 64 | D35: 34 | G35: chan130 | H35: 62 | I35: 130 | L35: chan226 | M35: 62 | N35: 226 | Q35: chan322 | R35: <= 50 | S35: 322 | V35: chan418 | W35: 65 | X35: 418 | AA35: chan514 | AB35: 61 | AC35: 514 | AF35: chan610 | AG35: 64 | AH35: 610 | AK35: chan706 | AL35: 64 | AM35: 706 | AP35: chan802 | AQ35: 58 | AR35: 802 | AU35: chan898 | AV35: 55 | AW35: 898 | AZ35: chan994 | BA35: 65 | BB35: 994
B36: chan35 | C36: 64 | D36: 35 | G36: chan131 | H36: 58 | I36: 131 | L36: chan227 | M36: 61 | N36: 227 | Q36: chan323 | R36: 193 | S36: 323 | V36: chan419 | W36: 65 | X36: 419 | AA36: chan515 | AB36: 60 | AC36: 515 | AF36: chan611 | AG36: 64 | AH36: 611 | AK36: chan707 | AL36: 63 | AM36: 707 | AP36: chan803 | AQ36: 55 | AR36: 803 | AU36: chan899 | AV36: 54 | AW36: 899 | AZ36: chan995 | BA36: 64 | BB36: 995
B37: chan36 | C37: 66 | D37: 36 | G37: chan132 | H37: 61 | I37: 132 | L37: chan228 | M37: 62 | N37: 228 | Q37: chan324 | R37: 65 | S37: 324 | V37: chan420 | W37: 65 | X37: 420 | AA37: chan516 | AB37: 62 | AC37: 516 | AF37: chan612 | AG37: 65 | AH37: 612 | AK37: chan708 | AL37: 65 | AM37: 708 | AP37: chan804 | AQ37: 57 | AR37: 804 | AU37: chan900 | AV37: 53 | AW37: 900 | AZ37: chan996 | BA37: 65 | BB37: 996
B38: chan37 | C38: 65 | D38: 37 | G38: chan133 | H38: 63 | I38: 133 | L38: chan229 | M38: 64 | N38: 229 | Q38: chan325 | R38: 64 | S38: 325 | V38: chan421 | W38: 66 | X38: 421 | AA38: chan517 | AB38: 64 | AC38: 517 | AF38: chan613 | AG38: 66 | AH38: 613 | AK38: chan709 | AL38: 67 | AM38: 709 | AP38: chan805 | AQ38: 59 | AR38: 805 | AU38: chan901 | AV38: 55 | AW38: 901 | AZ38: chan997 | BA38: 66 | BB38: 997
B39: chan38 | C39: 62 | D39: 38 | G39: chan134 | H39: 59 | I39: 134 | L39: chan230 | M39: 59 | N39: 230 | Q39: chan326 | R39: 61 | S39: 326 | V39: chan422 | W39: 62 | X39: 422 | AA39: chan518 | AB39: 59 | AC39: 518 | AF39: chan614 | AG39: 63 | AH39: 614 | AK39: chan710 | AL39: 63 | AM39: 710 | AP39: chan806 | AQ39: 55 | AR39: 806 | AU39: chan902 | AV39: 52 | AW39: 902 | AZ39: chan998 | BA39: 63 | BB39: 998
B40: chan39 | C40: 65 | D40: 39 | G40: chan135 | H40: 59 | I40: 135 | L40: chan231 | M40: 61 | N40: 231 | Q40: chan327 | R40: 63 | S40: 327 | V40: chan423 | W40: 56 | X40: 423 | AA40: chan519 | AB40: 61 | AC40: 519 | AF40: chan615 | AG40: 60 | AH40: 615 | AK40: chan711 | AL40: 65 | AM40: 711 | AP40: chan807 | AQ40: 57 | AR40: 807 | AU40: chan903 | AV40: 56 | AW40: 903 | AZ40: chan999 | BA40: 65 | BB40: 999
...

Sheet Array mapping
B2: WO-9001285
AN3: 1 | AO3: 9 | AP3: 17 | AQ3: 25 | AR3: 33 | AS3: 41 | AT3: 49 | AU3: 57 | AV3: A1 | AZ3: 513 | BA3: 521 | BB3: 529 | BC3: 537 | BD3: 545 | BE3: 553 | BF3: 561 | BG3: 569 | BH3: A9
B4: SN: 11388-000003 | AN4: 2 | AO4: 10 | AP4: 18 | AQ4: 26 | AR4: 34 | AS4: 42 | AT4: 50 | AU4: 58 | AV4: ='Array Impedance'!AW4 -> array ID: 1078-3 | AZ4: 514 | BA4: 522 | BB4: 530 | BC4: 538 | BD4: 546 | BE4: 554 | BF4: 562 | BG4: 570 | BH4: ='Array Impedance'!BI4 -> array ID: 1078-21
AN5: 3 | AO5: 11 | AP5: 19 | AQ5: 27 | AR5: 35 | AS5: 43 | AT5: 51 | AU5: 59 | AZ5: 515 | BA5: 523 | BB5: 531 | BC5: 539 | BD5: 547 | BE5: 555 | BF5: 563 | BG5: 571
AN6: 4 | AO6: 12 | AP6: 20 | AQ6: 28 | AR6: 36 | AS6: 44 | AT6: 52 | AU6: 60 | AZ6: 516 | BA6: 524 | BB6: 532 | BC6: 540 | BD6: 548 | BE6: 556 | BF6: 564 | BG6: 572
AN7: 5 | AO7: 13 | AP7: 21 | AQ7: 29 | AR7: 37 | AS7: 45 | AT7: 53 | AU7: 61 | AZ7: 517 | BA7: 525 | BB7: 533 | BC7: 541 | BD7: 549 | BE7: 557 | BF7: 565 | BG7: 573
AN8: 6 | AO8: 14 | AP8: 22 | AQ8: 30 | AR8: 38 | AS8: 46 | AT8: 54 | AU8: 62 | AZ8: 518 | BA8: 526 | BB8: 534 | BC8: 542 | BD8: 550 | BE8: 558 | BF8: 566 | BG8: 574
AN9: 7 | AO9: 15 | AP9: 23 | AQ9: 31 | AR9: 39 | AS9: 47 | AT9: 55 | AU9: 63 | AZ9: 519 | BA9: 527 | BB9: 535 | BC9: 543 | BD9: 551 | BE9: 559 | BF9: 567 | BG9: 575
AN10: 8 | AO10: 16 | AP10: 24 | AQ10: 32 | AR10: 40 | AS10: 48 | AT10: 56 | AU10: 64 | AZ10: 520 | BA10: 528 | BB10: 536 | BC10: 544 | BD10: 552 | BE10: 560 | BF10: 568 | BG10: 576
AN12: 65 | AO12: 73 | AP12: 81 | AQ12: 89 | AR12: 97 | AS12: 105 | AT12: 113 | AU12: 121 | AV12: A2 | AZ12: 577 | BA12: 585 | BB12: 593 | BC12: 601 | BD12: 609 | BE12: 617 | BF12: 625 | BG12: 633 | BH12: A10
AN13: 66 | AO13: 74 | AP13: 82 | AQ13: 90 | AR13: 98 | AS13: 106 | AT13: 114 | AU13: 122 | AV13: ='Array Impedance'!AW13 -> array ID: 1078-5 | AZ13: 578 | BA13: 586 | BB13: 594 | BC13: 602 | BD13: 610 | BE13: 618 | BF13: 626 | BG13: 634 | BH13: ='Array Impedance'!BI13 -> array ID: 1078-23
AN14: 67 | AO14: 75 | AP14: 83 | AQ14: 91 | AR14: 99 | AS14: 107 | AT14: 115 | AU14: 123 | AZ14: 579 | BA14: 587 | BB14: 595 | BC14: 603 | BD14: 611 | BE14: 619 | BF14: 627 | BG14: 635
AN15: 68 | AO15: 76 | AP15: 84 | AQ15: 92 | AR15: 100 | AS15: 108 | AT15: 116 | AU15: 124 | AZ15: 580 | BA15: 588 | BB15: 596 | BC15: 604 | BD15: 612 | BE15: 620 | BF15: 628 | BG15: 636
AN16: 69 | AO16: 77 | AP16: 85 | AQ16: 93 | AR16: 101 | AS16: 109 | AT16: 117 | AU16: 125 | AZ16: 581 | BA16: 589 | BB16: 597 | BC16: 605 | BD16: 613 | BE16: 621 | BF16: 629 | BG16: 637
AN17: 70 | AO17: 78 | AP17: 86 | AQ17: 94 | AR17: 102 | AS17: 110 | AT17: 118 | AU17: 126 | AZ17: 582 | BA17: 590 | BB17: 598 | BC17: 606 | BD17: 614 | BE17: 622 | BF17: 630 | BG17: 638
AN18: 71 | AO18: 79 | AP18: 87 | AQ18: 95 | AR18: 103 | AS18: 111 | AT18: 119 | AU18: 127 | AZ18: 583 | BA18: 591 | BB18: 599 | BC18: 607 | BD18: 615 | BE18: 623 | BF18: 631 | BG18: 639
N19: LGA bottom view (wire bonding side) | AN19: 72 | AO19: 80 | AP19: 88 | AQ19: 96 | AR19: 104 | AS19: 112 | AT19: 120 | AU19: 128 | AZ19: 584 | BA19: 592 | BB19: 600 | BC19: 608 | BD19: 616 | BE19: 624 | BF19: 632 | BG19: 640
M21: 1020 | N21: 1021 | O21: 1022 | P21: 1023 | Q21: 1024 | R21: R 7 | S21: R 8 | T21: R 2 | U21: R 1 | V21: 5 | W21: 4 | X21: 3 | Y21: 2 | Z21: 1 | AN21: 129 | AO21: 137 | AP21: 145 | AQ21: 153 | AR21: 161 | AS21: 169 | AT21: 177 | AU21: 185 | AV21: A3 | AZ21: 641 | BA21: 649 | BB21: 657 | BC21: 665 | BD21: 673 | BE21: 681 | BF21: 689 | BG21: 697 | BH21: A11
L22: 1012 | M22: 1013 | N22: 1014 | O22: 1015 | P22: 1016 | Q22: 1017 | R22: 1018 | S22: 1019 | T22: 13 | U22: 12 | V22: 11 | W22: 10 | X22: 9 | Y22: 8 | Z22: 7 | AA22: 6 | AN22: 130 | AO22: 138 | AP22: 146 | AQ22: 154 | AR22: 162 | AS22: 170 | AT22: 178 | AU22: 186 | AV22: ='Array Impedance'!AW22 -> array ID: 1078-7 | AZ22: 642 | BA22: 650 | BB22: 658 | BC22: 666 | BD22: 674 | BE22: 682 | BF22: 690 | BG22: 698 | BH22: ='Array Impedance'!BI22 -> array ID: 1078-25
K23: 1003 | L23: 1004 | M23: 1005 | N23: 1006 | O23: 1007 | P23: 1008 | Q23: 1009 | R23: 1010 | S23: 1011 | T23: 22 | U23: 21 | V23: 20 | W23: 19 | X23: 18 | Y23: 17 | Z23: 16 | AA23: 15 | AB23: 14 | AN23: 131 | AO23: 139 | AP23: 147 | AQ23: 155 | AR23: 163 | AS23: 171 | AT23: 179 | AU23: 187 | AZ23: 643 | BA23: 651 | BB23: 659 | BC23: 667 | BD23: 675 | BE23: 683 | BF23: 691 | BG23: 699
J24: 993 | K24: 994 | L24: 995 | M24: 996 | N24: 997 | O24: 998 | P24: 999 | Q24: 1000 | R24: 1001 | S24: 1002 | T24: 32 | U24: 31 | V24: 30 | W24: 29 | X24: 28 | Y24: 27 | Z24: 26 | AA24: 25 | AB24: 24 | AC24: 23 | AN24: 132 | AO24: 140 | AP24: 148 | AQ24: 156 | AR24: 164 | AS24: 172 | AT24: 180 | AU24: 188 | AZ24: 644 | BA24: 652 | BB24: 660 | BC24: 668 | BD24: 676 | BE24: 684 | BF24: 692 | BG24: 700
I25: 982 | J25: 983 | K25: 984 | L25: 985 | M25: 986 | N25: 987 | O25: 988 | P25: 989 | Q25: 990 | R25: 991 | S25: 992 | T25: 43 | U25: 42 | V25: 41 | W25: 40 | X25: 39 | Y25: 38 | Z25: 37 | AA25: 36 | AB25: 35 | AC25: 34 | AD25: 33 | AN25: 133 | AO25: 141 | AP25: 149 | AQ25: 157 | AR25: 165 | AS25: 173 | AT25: 181 | AU25: 189 | AZ25: 645 | BA25: 653 | BB25: 661 | BC25: 669 | BD25: 677 | BE25: 685 | BF25: 693 | BG25: 701
H26: 970 | I26: 971 | J26: 972 | K26: 973 | L26: 974 | M26: 975 | N26: 976 | O26: 977 | P26: 978 | Q26: 979 | R26: 980 | S26: 981 | T26: 55 | U26: 54 | V26: 53 | W26: 52 | X26: 51 | Y26: 50 | Z26: 49 | AA26: 48 | AB26: 47 | AC26: 46 | AD26: 45 | AE26: 44 | AN26: 134 | AO26: 142 | AP26: 150 | AQ26: 158 | AR26: 166 | AS26: 174 | AT26: 182 | AU26: 190 | AZ26: 646 | BA26: 654 | BB26: 662 | BC26: 670 | BD26: 678 | BE26: 686 | BF26: 694 | BG26: 702
G27: 957 | H27: 958 | I27: 959 | J27: 960 | K27: 961 | L27: 962 | M27: 963 | N27: 964 | O27: 965 | P27: 966 | Q27: 967 | R27: 968 | S27: 969 | T27: 68 | U27: 67 | V27: 66 | W27: 65 | X27: 64 | Y27: 63 | Z27: 62 | AA27: 61 | AB27: 60 | AC27: 59 | AD27: 58 | AE27: 57 | AF27: 56 | AN27: 135 | AO27: 143 | AP27: 151 | AQ27: 159 | AR27: 167 | AS27: 175 | AT27: 183 | AU27: 191 | AZ27: 647 | BA27: 655 | BB27: 663 | BC27: 671 | BD27: 679 | BE27: 687 | BF27: 695 | BG27: 703
F28: 943 | G28: 944 | H28: 945 | I28: 946 | J28: 947 | K28: 948 | L28: 949 | M28: 950 | N28: 951 | O28: 952 | P28: 953 | Q28: 954 | R28: 955 | S28: 956 | T28: 82 | U28: 81 | V28: 80 | W28: 79 | X28: 78 | Y28: 77 | Z28: 76 | AA28: 75 | AB28: 74 | AC28: 73 | AD28: 72 | AE28: 71 | AF28: 70 | AG28: 69 | AN28: 136 | AO28: 144 | AP28: 152 | AQ28: 160 | AR28: 168 | AS28: 176 | AT28: 184 | AU28: 192 | AZ28: 648 | BA28: 656 | BB28: 664 | BC28: 672 | BD28: 680 | BE28: 688 | BF28: 696 | BG28: 704
E29: 928 | F29: 929 | G29: 930 | H29: 931 | I29: 932 | J29: 933 | K29: 934 | L29: 935 | M29: 936 | N29: 937 | O29: 938 | P29: 939 | Q29: 940 | R29: 941 | S29: 942 | T29: 97 | U29: 96 | V29: 95 | W29: 94 | X29: 93 | Y29: 92 | Z29: 91 | AA29: 90 | AB29: 89 | AC29: 88 | AD29: 87 | AE29: 86 | AF29: 85 | AG29: 84 | AH29: 83
D30: 912 | E30: 913 | F30: 914 | G30: 915 | H30: 916 | I30: 917 | J30: 918 | K30: 919 | L30: 920 | M30: 921 | N30: 922 | O30: 923 | P30: 924 | Q30: 925 | R30: 926 | S30: 927 | T30: 113 | U30: 112 | V30: 111 | W30: 110 | X30: 109 | Y30: 108 | Z30: 107 | AA30: 106 | AB30: 105 | AC30: 104 | AD30: 103 | AE30: 102 | AF30: 101 | AG30: 100 | AH30: 99 | AI30: 98 | AN30: 193 | AO30: 201 | AP30: 209 | AQ30: 217 | AR30: 225 | AS30: 233 | AT30: 241 | AU30: 249 | AV30: A4 | AZ30: 705 | BA30: 713 | BB30: 721 | BC30: 729 | BD30: 737 | BE30: 745 | BF30: 753 | BG30: 761 | BH30: A12
C31: 895 | D31: 896 | E31: 897 | F31: 898 | G31: 899 | H31: 900 | I31: 901 | J31: 902 | K31: 903 | L31: 904 | M31: 905 | N31: 906 | O31: 907 | P31: 908 | Q31: 909 | R31: 910 | S31: 911 | T31: 130 | U31: 129 | V31: 128 | W31: 127 | X31: 126 | Y31: 125 | Z31: 124 | AA31: 123 | AB31: 122 | AC31: 121 | AD31: 120 | AE31: 119 | AF31: 118 | AG31: 117 | AH31: 116 | AI31: 115 | AJ31: 114 | AN31: 194 | AO31: 202 | AP31: 210 | AQ31: 218 | AR31: 226 | AS31: 234 | AT31: 242 | AU31: 250 | AV31: ='Array Impedance'!AW31 -> array ID: 1078-8 | AZ31: 706 | BA31: 714 | BB31: 722 | BC31: 730 | BD31: 738 | BE31: 746 | BF31: 754 | BG31: 762 | BH31: ='Array Impedance'!BI31 -> array ID: 1078-26
B32: 877 | C32: 878 | D32: 879 | E32: 880 | F32: 881 | G32: 882 | H32: 883 | I32: 884 | J32: 885 | K32: 886 | L32: 887 | M32: 888 | N32: 889 | O32: 890 | P32: 891 | Q32: 892 | R32: 893 | S32: 894 | T32: 148 | U32: 147 | V32: 146 | W32: 145 | X32: 144 | Y32: 143 | Z32: 142 | AA32: 141 | AB32: 140 | AC32: 139 | AD32: 138 | AE32: 137 | AF32: 136 | AG32: 135 | AH32: 134 | AI32: 133 | AJ32: 132 | AK32: 131 | AN32: 195 | AO32: 203 | AP32: 211 | AQ32: 219 | AR32: 227 | AS32: 235 | AT32: 243 | AU32: 251 | AZ32: 707 | BA32: 715 | BB32: 723 | BC32: 731 | BD32: 739 | BE32: 747 | BF32: 755 | BG32: 763
